<?xml version="1.0" encoding="UTF-8"?>
<!-- Generated by org.testng.reporters.JUnitReportReporter -->
<testsuite skipped="0" hostname="KDUGGIRA-LAP" name="TestNGPractice.Assertions" tests="3" failures="2" timestamp="26 Nov 2020 10:57:49 GMT" time="0.026" errors="0">
  <testcase name="softAssertTest" time="0.004" classname="TestNGPractice.Assertions"/>
  <testcase name="softAssertTest2" time="0.003" classname="TestNGPractice.Assertions">
    <failure type="java.lang.AssertionError" message="The following asserts failed:
	expected [12] but found [10],
	expected [12] but found [10]">
      <![CDATA[java.lang.AssertionError: The following asserts failed:
	expected [12] but found [10],
	expected [12] but found [10]
	at org.testng.asserts.SoftAssert.assertAll(SoftAssert.java:43)
	at TestNGPractice.Assertions.softAssertTest2(Assertions.java:39)
	at sun.reflect.NativeMethodAccessorImpl.invoke0(Native Method)
	at sun.reflect.NativeMethodAccessorImpl.invoke(Unknown Source)
	at sun.reflect.DelegatingMethodAccessorImpl.invoke(Unknown Source)
	at java.lang.reflect.Method.invoke(Unknown Source)
	at org.testng.internal.MethodInvocationHelper.invokeMethod(MethodInvocationHelper.java:108)
	at org.testng.internal.Invoker.invokeMethod(Invoker.java:669)
	at org.testng.internal.Invoker.invokeTestMethod(Invoker.java:877)
	at org.testng.internal.Invoker.invokeTestMethods(Invoker.java:1201)
	at org.testng.internal.TestMethodWorker.invokeTestMethods(TestMethodWorker.java:125)
	at org.testng.internal.TestMethodWorker.run(TestMethodWorker.java:109)
	at org.testng.TestRunner.privateRun(TestRunner.java:776)
	at org.testng.TestRunner.run(TestRunner.java:634)
	at org.testng.SuiteRunner.runTest(SuiteRunner.java:425)
	at org.testng.SuiteRunner.runSequentially(SuiteRunner.java:420)
	at org.testng.SuiteRunner.privateRun(SuiteRunner.java:385)
	at org.testng.SuiteRunner.run(SuiteRunner.java:334)
	at org.testng.SuiteRunnerWorker.runSuite(SuiteRunnerWorker.java:52)
	at org.testng.SuiteRunnerWorker.run(SuiteRunnerWorker.java:86)
	at org.testng.TestNG.runSuitesSequentially(TestNG.java:1318)
	at org.testng.TestNG.runSuitesLocally(TestNG.java:1243)
	at org.testng.TestNG.runSuites(TestNG.java:1161)
	at org.testng.TestNG.run(TestNG.java:1129)
	at org.testng.remote.AbstractRemoteTestNG.run(AbstractRemoteTestNG.java:115)
	at org.testng.remote.RemoteTestNG.initAndRun(RemoteTestNG.java:251)
	at org.testng.remote.RemoteTestNG.main(RemoteTestNG.java:77)
]]>
    </failure>
  </testcase> <!-- softAssertTest2 -->
  <testcase name="hardAssertTest" time="0.019" classname="TestNGPractice.Assertions">
    <failure type="java.lang.AssertionError" message="expected [12] but found [10]">
      <![CDATA[java.lang.AssertionError: expected [12] but found [10]
	at org.testng.Assert.fail(Assert.java:93)
	at org.testng.Assert.failNotEquals(Assert.java:512)
	at org.testng.Assert.assertEqualsImpl(Assert.java:134)
	at org.testng.Assert.assertEquals(Assert.java:115)
	at org.testng.Assert.assertEquals(Assert.java:388)
	at org.testng.Assert.assertEquals(Assert.java:398)
	at TestNGPractice.Assertions.hardAssertTest(Assertions.java:18)
	at sun.reflect.NativeMethodAccessorImpl.invoke0(Native Method)
	at sun.reflect.NativeMethodAccessorImpl.invoke(Unknown Source)
	at sun.reflect.DelegatingMethodAccessorImpl.invoke(Unknown Source)
	at java.lang.reflect.Method.invoke(Unknown Source)
	at org.testng.internal.MethodInvocationHelper.invokeMethod(MethodInvocationHelper.java:108)
	at org.testng.internal.Invoker.invokeMethod(Invoker.java:669)
	at org.testng.internal.Invoker.invokeTestMethod(Invoker.java:877)
	at org.testng.internal.Invoker.invokeTestMethods(Invoker.java:1201)
	at org.testng.internal.TestMethodWorker.invokeTestMethods(TestMethodWorker.java:125)
	at org.testng.internal.TestMethodWorker.run(TestMethodWorker.java:109)
	at org.testng.TestRunner.privateRun(TestRunner.java:776)
	at org.testng.TestRunner.run(TestRunner.java:634)
	at org.testng.SuiteRunner.runTest(SuiteRunner.java:425)
	at org.testng.SuiteRunner.runSequentially(SuiteRunner.java:420)
	at org.testng.SuiteRunner.privateRun(SuiteRunner.java:385)
	at org.testng.SuiteRunner.run(SuiteRunner.java:334)
	at org.testng.SuiteRunnerWorker.runSuite(SuiteRunnerWorker.java:52)
	at org.testng.SuiteRunnerWorker.run(SuiteRunnerWorker.java:86)
	at org.testng.TestNG.runSuitesSequentially(TestNG.java:1318)
	at org.testng.TestNG.runSuitesLocally(TestNG.java:1243)
	at org.testng.TestNG.runSuites(TestNG.java:1161)
	at org.testng.TestNG.run(TestNG.java:1129)
	at org.testng.remote.AbstractRemoteTestNG.run(AbstractRemoteTestNG.java:115)
	at org.testng.remote.RemoteTestNG.initAndRun(RemoteTestNG.java:251)
	at org.testng.remote.RemoteTestNG.main(RemoteTestNG.java:77)
]]>
    </failure>
  </testcase> <!-- hardAssertTest -->
</testsuite> <!-- TestNGPractice.Assertions -->
